Workbook

Sheet Legend
A1: CareSaath — Dev Tracker
A3: Source | B3: CareSaath SRS (Sep 23, 2026). Tasks are derived from SRS requirements; nothing is invented. Unknowns are marked TBD (see Open Questions sheet).
A4: Companion docs | B4: CARESAATH_ERD.md, CARESAATH_TRD.md
A5: Sheets | B5: Summary (auto-counts) · Backend · Frontend · Open Questions
A6: Cells you edit | B6: Owner, Status, Start, Due, Notes (blue text). Status uses a dropdown. Everything else is pre-filled from the SRS.
A7: Status values | B7: Not Started · In Progress · In Review · Blocked · Done
A8: Priority | B8: High = needed for a working MVP flow or required by SRS constraints. Medium/Low = can follow. Priority is a proposal; adjust freely.
A9: Phases | B9: P0 Setup · P1 Core (auth, onboarding, verification) · P2 Booking & Visits · P3 Payments · P4 Safety & Admin · P5 Hardening
A10: Estimates / dates | B10: Not filled in. Effort estimates need team size and decisions in Open Questions (TBD).
A11: Frontend note | B11: Customer-app framework and caregiver panel (web vs native) are undecided in the SRS; see Open Questions #1 and #2.

Sheet Summary
A1: Progress Summary
A3: Status | B3: Backend | C3: Frontend | D3: Total
A4: Not Started | B4: =COUNTIF(Backend!$H$2:$H$500,A4) -> 67 | C4: =COUNTIF(Frontend!$I$2:$I$500,A4) -> 48 | D4: =B4+C4 -> 115
A5: In Progress | B5: =COUNTIF(Backend!$H$2:$H$500,A5) -> 0 | C5: =COUNTIF(Frontend!$I$2:$I$500,A5) -> 0 | D5: =B5+C5 -> 0
A6: In Review | B6: =COUNTIF(Backend!$H$2:$H$500,A6) -> 0 | C6: =COUNTIF(Frontend!$I$2:$I$500,A6) -> 0 | D6: =B6+C6 -> 0
A7: Blocked | B7: =COUNTIF(Backend!$H$2:$H$500,A7) -> 0 | C7: =COUNTIF(Frontend!$I$2:$I$500,A7) -> 0 | D7: =B7+C7 -> 0
A8: Done | B8: =COUNTIF(Backend!$H$2:$H$500,A8) -> 0 | C8: =COUNTIF(Frontend!$I$2:$I$500,A8) -> 0 | D8: =B8+C8 -> 0
A9: Total tasks | B9: =SUM(B4:B8) -> 67 | C9: =SUM(C4:C8) -> 48 | D9: =SUM(D4:D8) -> 115
A10: % Done | B10: =IF(B9=0,0,B8/B9) -> 0 | C10: =IF(C9=0,0,C8/C9) -> 0 | D10: =IF(D9=0,0,D8/D9) -> 0
A12: Tasks by phase
A13: Phase | B13: Total | C13: Done | D13: % Done
A14: P0 Setup | B14: =COUNTIF(Backend!$E$2:$E$500,A14)+COUNTIF(Frontend!$E$2:$E$500,A14) -> 12 | C14: =COUNTIFS(Backend!$E$2:$E$500,A14,Backend!$H$2:$H$500,"Done")+COUNTIFS(Frontend!$E$2:$E$500,A14,Frontend!$I$2:$I$500,"Done") -> 0 | D14: =IF(B14=0,0,C14/B14) -> 0
A15: P1 Core | B15: =COUNTIF(Backend!$E$2:$E$500,A15)+COUNTIF(Frontend!$E$2:$E$500,A15) -> 24 | C15: =COUNTIFS(Backend!$E$2:$E$500,A15,Backend!$H$2:$H$500,"Done")+COUNTIFS(Frontend!$E$2:$E$500,A15,Frontend!$I$2:$I$500,"Done") -> 0 | D15: =IF(B15=0,0,C15/B15) -> 0
A16: P2 Booking & Visits | B16: =COUNTIF(Backend!$E$2:$E$500,A16)+COUNTIF(Frontend!$E$2:$E$500,A16) -> 31 | C16: =COUNTIFS(Backend!$E$2:$E$500,A16,Backend!$H$2:$H$500,"Done")+COUNTIFS(Frontend!$E$2:$E$500,A16,Frontend!$I$2:$I$500,"Done") -> 0 | D16: =IF(B16=0,0,C16/B16) -> 0
A17: P3 Payments | B17: =COUNTIF(Backend!$E$2:$E$500,A17)+COUNTIF(Frontend!$E$2:$E$500,A17) -> 15 | C17: =COUNTIFS(Backend!$E$2:$E$500,A17,Backend!$H$2:$H$500,"Done")+COUNTIFS(Frontend!$E$2:$E$500,A17,Frontend!$I$2:$I$500,"Done") -> 0 | D17: =IF(B17=0,0,C17/B17) -> 0
A18: P4 Safety & Admin | B18: =COUNTIF(Backend!$E$2:$E$500,A18)+COUNTIF(Frontend!$E$2:$E$500,A18) -> 20 | C18: =COUNTIFS(Backend!$E$2:$E$500,A18,Backend!$H$2:$H$500,"Done")+COUNTIFS(Frontend!$E$2:$E$500,A18,Frontend!$I$2:$I$500,"Done") -> 0 | D18: =IF(B18=0,0,C18/B18) -> 0
A19: P5 Hardening | B19: =COUNTIF(Backend!$E$2:$E$500,A19)+COUNTIF(Frontend!$E$2:$E$500,A19) -> 13 | C19: =COUNTIFS(Backend!$E$2:$E$500,A19,Backend!$H$2:$H$500,"Done")+COUNTIFS(Frontend!$E$2:$E$500,A19,Frontend!$I$2:$I$500,"Done") -> 0 | D19: =IF(B19=0,0,C19/B19) -> 0
A22: Open questions still unresolved | B22: =COUNTIF('Open Questions'!$F$2:$F$200,"Open") -> 31

Sheet Backend
A1: ID | B1: Module | C1: Task | D1: SRS Ref | E1: Phase | F1: Priority | G1: Owner | H1: Status | I1: Start | J1: Due | K1: Notes
A2: BE-001 | B2: Setup | C2: Initialise NestJS + TypeScript project, npm scripts, lint/format | D2: TRD §3.3 | E2: P0 Setup | F2: High | H2: Not Started
A3: BE-002 | B3: Setup | C3: Docker Compose: postgres, redis, minio, mailhog, backend | D3: TRD §10.1 | E3: P0 Setup | F3: High | H3: Not Started | K3: Version pins TBD
A4: BE-003 | B4: Setup | C4: Prisma setup, initial schema from ERD, migrations, seed script | D4: ERD | E4: P0 Setup | F4: High | H4: Not Started
A5: BE-004 | B5: Setup | C5: Config module + .env validation; tunable-values table | D5: TRD §4 | E5: P0 Setup | F5: High | H5: Not Started | K5: Holds TBD windows/limits
A6: BE-005 | B6: Setup | C6: Global validation, exception filter, logging, pagination, Swagger | D6: TRD §5 | E6: P0 Setup | F6: Medium | H6: Not Started
A7: BE-006 | B7: Setup | C7: MinIO service wrapper (upload, pre-signed URL, bucket policy) | D7: TRD §7 | E7: P0 Setup | F7: High | H7: Not Started
A8: BE-007 | B8: Setup | C8: CI pipeline (install, lint, type-check, test, build) | D8: TRD §10.4 | E8: P0 Setup | F8: Medium | H8: Not Started | K8: CI tool TBD
A9: BE-008 | B9: Auth | C9: OTP request endpoint (generate, hash, store in Redis, send SMS) | D9: FR-C1 | E9: P1 Core | F9: High | H9: Not Started | K9: SMS vendor TBD
A10: BE-009 | B10: Auth | C10: OTP verify endpoint, issue JWT access + refresh | D10: FR-C1 | E10: P1 Core | F10: High | H10: Not Started | K10: TTLs TBD
A11: BE-010 | B11: Auth | C11: Refresh/logout, token deny-list in Redis | D11: TRD §5.1 | E11: P1 Core | F11: Medium | H11: Not Started
A12: BE-011 | B12: Auth | C12: Role guards (Customer/Caregiver/Admin) + ownership checks | D12: SRS §2.3 | E12: P1 Core | F12: High | H12: Not Started
A13: BE-012 | B13: Auth | C13: OTP/login rate limiting | D13: TRD §7 | E13: P1 Core | F13: High | H13: Not Started | K13: Limits TBD
A14: BE-013 | B14: Auth | C14: Admin login method | D14: SRS §8.1 | E14: P1 Core | F14: Medium | H14: Not Started | K14: TBD: SRS silent
A15: BE-014 | B15: Users | C15: User CRUD, language preference (EN/UR), status handling | D15: SRS §2.5 | E15: P1 Core | F15: Medium | H15: Not Started
A16: BE-015 | B16: Patients | C16: Patient profile CRUD (self / family member, medical context) | D16: FR-C2 | E16: P1 Core | F16: High | H16: Not Started | K16: Fields TBD; encrypt
A17: BE-016 | B17: Addresses | C17: Address CRUD with lat/lng | D17: FR-C7 | E17: P1 Core | F17: High | H17: Not Started
A18: BE-017 | B18: Caregiver | C18: Caregiver registration (name, CNIC, license no.) | D18: FR-CG1 | E18: P1 Core | F18: High | H18: Not Started | K18: Encrypt CNIC
A19: BE-018 | B19: Caregiver | C19: Certificate/license document upload to MinIO | D19: FR-CG1 | E19: P1 Core | F19: High | H19: Not Started
A20: BE-019 | B20: Caregiver | C20: Profile: specialty, service area, rate per visit | D20: FR-CG3 | E20: P1 Core | F20: High | H20: Not Started | K20: Service-area model TBD
A21: BE-020 | B21: Caregiver | C21: Public caregiver profile endpoint (quals, license no., experience, ratings, rate) | D21: FR-C4 | E21: P1 Core | F21: High | H21: Not Started
A22: BE-021 | B22: Verification | C22: Admin queue + approve/reject endpoints, block unapproved from search | D22: FR-CG2, FR-A1 | E22: P1 Core | F22: High | H22: Not Started | K22: No unverified profile goes live
A23: BE-022 | B23: Verification | C23: Periodic re-verification due dates + reminders | D23: FR-A2 | E23: P4 Safety & Admin | F23: Medium | H23: Not Started | K23: Interval TBD (annual example)
A24: BE-023 | B24: Availability | C24: Weekly availability rules CRUD | D24: FR-CG4 | E24: P2 Booking & Visits | F24: High | H24: Not Started
A25: BE-024 | B25: Availability | C25: Blocked dates CRUD | D25: FR-CG4 | E25: P2 Booking & Visits | F25: High | H25: Not Started
A26: BE-025 | B26: Search | C26: Caregiver search by specialty, location, availability | D26: FR-C3 | E26: P2 Booking & Visits | F26: High | H26: Not Started
A27: BE-026 | B27: Search | C27: DB indexes + Redis caching to meet <3s on 3G | D27: SRS §6 | E27: P2 Booking & Visits | F27: High | H27: Not Started | K27: Target definition TBD
A28: BE-027 | B28: Booking | C28: Create single booking (date, time window, address, patient) | D28: FR-C6, FR-C7 | E28: P2 Booking & Visits | F28: High | H28: Not Started
A29: BE-028 | B29: Booking | C29: Recurring booking: generate one visit per occurrence | D29: FR-C6 | E29: P2 Booking & Visits | F29: High | H29: Not Started | K29: Allowed patterns TBD
A30: BE-029 | B30: Booking | C30: Double-booking prevention (transactional availability check) | D30: FR-CG4 | E30: P2 Booking & Visits | F30: High | H30: Not Started | K30: Design
A31: BE-030 | B31: Booking | C31: Prescription/care-plan upload with booking | D31: FR-C5 | E31: P2 Booking & Visits | F31: High | H31: Not Started | K31: File rules TBD
A32: BE-031 | B32: Booking | C32: Caregiver accept/decline within response window | D32: FR-CG5 | E32: P2 Booking & Visits | F32: High | H32: Not Started | K32: Window + timeout behaviour TBD
A33: BE-032 | B33: Booking | C33: Customer cancel/reschedule within notice window | D33: FR-C13 | E33: P2 Booking & Visits | F33: High | H33: Not Started | K33: Window TBD; Cancelled state is a gap-fill
A34: BE-033 | B34: Visits | C34: Visit state machine (Requested → … → Completed) + history table | D34: FR-C9, SRS §8.2 | E34: P2 Booking & Visits | F34: High | H34: Not Started
A35: BE-034 | B35: Visits | C35: En-route endpoint | D35: FR-C9 | E35: P2 Booking & Visits | F35: Medium | H35: Not Started | K35: Trigger (manual vs auto) TBD
A36: BE-035 | B36: Visits | C36: Check-in/check-out via GPS or OTP, store coordinates | D36: FR-CG7 | E36: P2 Booking & Visits | F36: High | H36: Not Started | K36: GPS radius TBD
A37: BE-036 | B37: Visits | C37: Visit note submit (moves to Completed) + customer view | D37: FR-CG8, FR-C11 | E37: P2 Booking & Visits | F37: High | H37: Not Started
A38: BE-037 | B38: Visits | C38: Caregiver view of patient context + prescription (secured access) | D38: FR-CG6 | E38: P2 Booking & Visits | F38: High | H38: Not Started | K38: Only assigned caregiver + admin
A39: BE-038 | B39: Notifications | C39: Notification service + event triggers on status change | D39: FR-C10 | E39: P2 Booking & Visits | F39: High | H39: Not Started
A40: BE-039 | B40: Notifications | C40: SMS integration | D40: FR-C10, SRS §7.3 | E40: P2 Booking & Visits | F40: High | H40: Not Started | K40: Vendor TBD
...

Sheet Frontend
A1: ID | B1: Module | C1: Task | D1: SRS Ref | E1: Phase | F1: Priority | G1: Surface | H1: Owner | I1: Status | J1: Start | K1: Due | L1: Notes
A2: FE-001 | B2: Setup | C2: Next.js + TypeScript project, lint, folder structure | D2: TRD §3.3 | E2: P0 Setup | F2: High | G2: Admin / Caregiver (Next.js) | I2: Not Started | L2: Admin + caregiver (if web)
A3: FE-002 | B3: Setup | C3: Customer app framework decision and project setup | D3: SRS §7.1 | E3: P0 Setup | F3: High | G3: Customer | I3: Not Started | L3: TBD: native vs other
A4: FE-003 | B4: Setup | C4: i18n setup (English/Urdu) with RTL support | D4: SRS §2.5, §6 | E4: P0 Setup | F4: High | G4: Shared | I4: Not Started
A5: FE-004 | B5: Setup | C5: Typed API client from OpenAPI + auth/token handling | D5: TRD §9 | E5: P0 Setup | F5: High | G5: Shared | I5: Not Started
A6: FE-005 | B6: Setup | C6: Design system: tokens, components, large-text mode | D6: SRS §7.1 | E6: P0 Setup | F6: Medium | G6: Shared | I6: Not Started
A7: FE-006 | B7: Shared | C7: Language switcher in settings | D7: SRS §6 | E7: P1 Core | F7: Medium | G7: Shared | I7: Not Started
A8: FE-007 | B8: Customer | C8: Phone + OTP login screens | D8: FR-C1 | E8: P1 Core | F8: High | G8: Customer | I8: Not Started
A9: FE-008 | B9: Customer | C9: Patient profile create/edit (self or family) | D9: FR-C2 | E9: P1 Core | F9: High | G9: Customer | I9: Not Started | L9: Fields TBD
A10: FE-009 | B10: Customer | C10: Saved addresses + map pin picker | D10: FR-C7 | E10: P1 Core | F10: High | G10: Customer | I10: Not Started | L10: Maps provider TBD
A11: FE-010 | B11: Customer | C11: Caregiver search + filters (specialty, location, availability) | D11: FR-C3 | E11: P2 Booking & Visits | F11: High | G11: Customer | I11: Not Started
A12: FE-011 | B12: Customer | C12: Caregiver profile screen (quals, license no., experience, ratings, rate) | D12: FR-C4 | E12: P2 Booking & Visits | F12: High | G12: Customer | I12: Not Started
A13: FE-012 | B13: Customer | C13: Booking flow: single or recurring, date, time window, address | D13: FR-C6, FR-C7 | E13: P2 Booking & Visits | F13: High | G13: Customer | I13: Not Started
A14: FE-013 | B14: Customer | C14: Prescription/care-plan upload in booking | D14: FR-C5 | E14: P2 Booking & Visits | F14: High | G14: Customer | I14: Not Started
A15: FE-014 | B15: Customer | C15: Visit status tracking screen | D15: FR-C9 | E15: P2 Booking & Visits | F15: High | G15: Customer | I15: Not Started
A16: FE-015 | B16: Customer | C16: Caregiver identity + photo shown before visit | D16: SRS §9.2 | E16: P2 Booking & Visits | F16: High | G16: Customer | I16: Not Started
A17: FE-016 | B17: Customer | C17: Cancel/reschedule UI | D17: FR-C13 | E17: P2 Booking & Visits | F17: High | G17: Customer | I17: Not Started | L17: Window TBD
A18: FE-017 | B18: Customer | C18: View caregiver visit notes | D18: FR-C11 | E18: P2 Booking & Visits | F18: Medium | G18: Customer | I18: Not Started
A19: FE-018 | B19: Customer | C19: Push/notification handling | D19: FR-C10 | E19: P2 Booking & Visits | F19: Medium | G19: Customer | I19: Not Started
A20: FE-019 | B20: Customer | C20: Payment screens (cash, card, JazzCash, Easypaisa) | D20: FR-C8 | E20: P3 Payments | F20: High | G20: Customer | I20: Not Started
A21: FE-020 | B21: Customer | C21: Rating and review screen | D21: FR-C12 | E21: P3 Payments | F21: Medium | G21: Customer | I21: Not Started
A22: FE-021 | B22: Customer | C22: Safety complaint form tied to a visit | D22: FR-C14 | E22: P4 Safety & Admin | F22: High | G22: Customer | I22: Not Started
A23: FE-022 | B23: Customer | C23: SOS button during active visit | D23: SRS §9.2 | E23: P4 Safety & Admin | F23: High | G23: Customer | I23: Not Started
A24: FE-023 | B24: Customer | C24: Large-text / simple-navigation option | D24: SRS §7.1 | E24: P5 Hardening | F24: Medium | G24: Customer | I24: Not Started
A25: FE-024 | B25: Caregiver | C25: Registration form (name, CNIC, license, certificate upload) | D25: FR-CG1 | E25: P1 Core | F25: High | G25: Caregiver | I25: Not Started
A26: FE-025 | B26: Caregiver | C26: Verification status screen (pending/approved/rejected) | D26: FR-CG2 | E26: P1 Core | F26: High | G26: Caregiver | I26: Not Started
A27: FE-026 | B27: Caregiver | C27: Profile: specialty, service area, rate | D27: FR-CG3 | E27: P1 Core | F27: High | G27: Caregiver | I27: Not Started
A28: FE-027 | B28: Caregiver | C28: Weekly availability + blocked dates | D28: FR-CG4 | E28: P2 Booking & Visits | F28: High | G28: Caregiver | I28: Not Started
A29: FE-028 | B29: Caregiver | C29: Incoming requests list with accept/decline + countdown | D29: FR-CG5 | E29: P2 Booking & Visits | F29: High | G29: Caregiver | I29: Not Started
... A34: FE-033 | B34: Caregiver | C34: Safety/access issue report | D34: FR-CG10 | E34: P4 Safety & Admin | F34: High | G34: Caregiver | I34: Not Started
A35: FE-034 | B35: Admin | C35: Admin login + layout/navigation | D35: SRS §7.1 | E35: P1 Core | F35: High | G35: Admin | I35: Not Started | L35: Login method TBD
A36: FE-035 | B36: Admin | C36: Caregiver verification queue: view documents, approve/reject | D36: FR-A1 | E36: P1 Core | F36: High | G36: Admin | I36: Not Started
A37: FE-036 | B37: Admin | C37: Suspend/deactivate caregiver | D37: FR-A3 | E37: P4 Safety & Admin | F37: High | G37: Admin | I37: Not Started
A38: FE-037 | B38: Admin | C38: Re-verification list/reminders | D38: FR-A2 | E38: P4 Safety & Admin | F38: Medium | G38: Admin | I38: Not Started
A39: FE-038 | B39: Admin | C39: Commission rate settings | D39: FR-A4 | E39: P3 Payments | F39: High | G39: Admin | I39: Not Started
A40: FE-039 | B40: Admin | C40: Safety incident console with priority and audit trail | D40: FR-A6 | E40: P4 Safety & Admin | F40: High | G40: Admin | I40: Not Started
A41: FE-040 | B41: Admin | C41: Dispute mediation screens | D41: FR-A7 | E41: P4 Safety & Admin | F41: Medium | G41: Admin | I41: Not Started
A42: FE-041 | B42: Admin | C42: Promo code management | D42: FR-A8 | E42: P4 Safety & Admin | F42: Low | G42: Admin | I42: Not Started
A43: FE-042 | B43: Admin | C43: Analytics dashboard | D43: FR-A5 | E43: P4 Safety & Admin | F43: Medium | G43: Admin | I43: Not Started
A44: FE-043 | B44: Admin | C44: Report export (CSV/Excel) | D44: FR-A9 | E44: P4 Safety & Admin | F44: Medium | G44: Admin | I44: Not Started
...

Sheet Open Questions
A1: # | B1: Open question (TBD) | C1: Affects | D1: Suggested decider | E1: Decision | F1: Status
A2: 1 | B2: Caregiver panel: web (SRS §2.4) or native app (SRS §7.1)? | C2: Frontend scope, staffing | D2: Product | F2: Open
A3: 2 | B3: Mobile framework for customer app (stack has Next.js only) | C3: Customer app delivery | D3: Tech lead | F3: Open
A4: 3 | B4: Pilot cities (1–2) and service-area model | C4: Search design, seeding | D4: Product | F4: Open
A5: 4 | B5: Fields inside 'basic medical context' (FR-C2) | C5: Patient table, forms | D5: Product / Compliance | F5: Open
A6: 5 | B6: Specialty list: elderly care and attendant appear in some places only | C6: Enums, search filters | D6: Product | F6: Open
A7: 6 | B7: Cancellation/reschedule notice window (FR-C13) | C7: Rules, UI | D7: Product | F7: Open
A8: 7 | B8: Caregiver response window and timeout behaviour (FR-CG5) | C8: Booking flow | D8: Product | F8: Open
A9: 8 | B9: Cancelled state missing from SRS §8.2 lifecycle | C9: State machine | D9: Product | F9: Open
A10: 9 | B10: Who triggers 'En Route' (caregiver or automatic) | C10: Visit flow | D10: Product | F10: Open
A11: 10 | B11: GPS radius / OTP flow for check-in | C11: Check-in rules | D11: Product | F11: Open
A12: 11 | B12: Payment per visit vs per booking; refund rules | C12: Payments schema | D12: Product / Finance | F12: Open
A13: 12 | B13: Cash-on-visit commission settlement | C13: Finance design | D13: Finance | F13: Open
... A32: 31 | B32: Promo code types; platform-wide discount scope | C32: Promos | D32: Business | F32: Open
